<?xml version="1.0" encoding="utf-8"?>
<!-- =================================================================================== -->
<!-- |    This document was autogenerated by xacro from ar3.xacro                      | -->
<!-- |    EDITING THIS FILE BY HAND IS NOT RECOMMENDED                                 | -->
<!-- =================================================================================== -->
<!-- Revolute-Revolute Manipulator -->
<robot name="ar3">
  <material name="black">
    <color rgba="0.0 0.0 0.0 1.0"/>
  </material>
  <material name="blue">
    <color rgba="0.0 0.0 0.8 1.0"/>
  </material>
  <material name="green">
    <color rgba="0.0 0.8 0.0 1.0"/>
  </material>
  <material name="grey">
    <color rgba="0.2 0.2 0.2 1.0"/>
  </material>
  <material name="orange">
    <color rgba="1.0 0.423529411765 0.0392156862745 1.0"/>
  </material>
  <material name="brown">
    <color rgba="0.870588235294 0.811764705882 0.764705882353 1.0"/>
  </material>
  <material name="red">
    <color rgba="0.8 0.0 0.0 1.0"/>
  </material>
  <material name="white">
    <color rgba="1.0 1.0 1.0 1.0"/>
  </material>
  <!-- Used for fixing robot to Gazebo 'base_link' -->
  <link name="world"/>
  <!-- Robot to Environment-->
  <joint name="BaseJoint" type="fixed">
    <parent link="world"/>
    <child link="base"/>
    <origin rpy="0 0 0" xyz="0 0 0"/>
    <axis xyz="0 0 1"/>
    <dynamics damping="0.7"/>
  </joint>
  <!-- BASE -->
  <link name="base">
    <collision>
      <origin rpy="0 0 0" xyz="0 0 0"/>
      <geometry>
        <mesh filename="file:///home/kpdudek/Robotics/src/ar3/urdf/meshes/Base.dae"/>
      </geometry>
    </collision>
    <visual>
      <origin rpy="0 0 0" xyz="0 0 0"/>
      <geometry>
        <mesh filename="file:///home/kpdudek/Robotics/src/ar3/urdf/meshes/Base.dae"/>
      </geometry>
    </visual>
  </link>
  <!-- Link 1 -->
  <link name="link1">
    <collision>
      <origin rpy="0 0 0" xyz="0 0 0"/>
      <geometry>
        <mesh filename="file:///home/kpdudek/Robotics/src/ar3/urdf/meshes/Link1.dae"/>
      </geometry>
    </collision>
    <visual>
      <origin rpy="0 0 0" xyz="0 0 0"/>
      <geometry>
        <mesh filename="file:///home/kpdudek/Robotics/src/ar3/urdf/meshes/Link1.dae"/>
      </geometry>
    </visual>
  </link>
  <!-- JOINT 1 -->
  <joint name="joint1" type="revolute">
    <parent link="base"/>
    <child link="link1"/>
    <origin rpy="0 0 0" xyz="0 0 0"/>
    <axis xyz="0 0 1"/>
    <dynamics damping="0.7"/>
    <limit effort="30.0" lower="-1.57" upper="1.57" velocity="10.0"/>
  </joint>
  <!-- Link 2 -->
  <link name="link2">
    <collision>
      <origin rpy="0 0 0" xyz="0 0 0"/>
      <geometry>
        <mesh filename="file:///home/kpdudek/Robotics/src/ar3/urdf/meshes/Link2.dae"/>
      </geometry>
    </collision>
    <visual>
      <origin rpy="0 0 0" xyz="0 0 0"/>
      <geometry>
        <mesh filename="file:///home/kpdudek/Robotics/src/ar3/urdf/meshes/Link2.dae"/>
      </geometry>
    </visual>
  </link>
  <!-- JOINT 2 -->
  <joint name="joint2" type="revolute">
    <parent link="link1"/>
    <child link="link2"/>
    <origin rpy="0 0 0" xyz="0.0508 -0.06786547 0.1390754"/>
    <axis xyz="1 0 0"/>
    <dynamics damping="0.7"/>
    <limit effort="30.0" lower="-0.5" upper="1.57" velocity="10.0"/>
  </joint>
  <!-- Link 3 -->
  <link name="link3">
    <collision>
      <origin rpy="0 0 0" xyz="0 0 0"/>
      <geometry>
        <mesh filename="file:///home/kpdudek/Robotics/src/ar3/urdf/meshes/Link3.dae"/>
      </geometry>
    </collision>
    <visual>
      <origin rpy="0 0 0" xyz="0 0 0"/>
      <geometry>
        <mesh filename="file:///home/kpdudek/Robotics/src/ar3/urdf/meshes/Link3.dae"/>
      </geometry>
    </visual>
  </link>
  <!-- JOINT 3 -->
  <joint name="joint3" type="revolute">
    <parent link="link2"/>
    <child link="link3"/>
    <origin rpy="0 0 0" xyz="-0.015 0 0.305"/>
    <axis xyz="1 0 0"/>
    <dynamics damping="0.7"/>
    <limit effort="30.0" lower="-0.1" upper="2.0" velocity="10.0"/>
  </joint>
  <!-- LINK 4-->
  <link name="link4">
    <collision>
      <origin rpy="0 0 0" xyz="0 0 0"/>
      <geometry>
        <mesh filename="file:///home/kpdudek/Robotics/src/ar3/urdf/meshes/Link4.dae"/>
      </geometry>
    </collision>
    <visual>
      <origin rpy="0 0 0" xyz="0 0 0"/>
      <geometry>
        <mesh filename="file:///home/kpdudek/Robotics/src/ar3/urdf/meshes/Link4.dae"/>
      </geometry>
    </visual>
  </link>
  <!-- JOINT 4 -->
  <joint name="joint4" type="revolute">
    <parent link="link3"/>
    <child link="link4"/>
    <origin rpy="0 0 0" xyz="-0.036 0 0.05"/>
    <axis xyz="0 0 1"/>
    <dynamics damping="0.7"/>
    <limit effort="30.0" lower="-1.57" upper="1.57" velocity="10.0"/>
  </joint>
  <!-- LINK 5-->
  <link name="link5">
    <collision>
      <origin rpy="0 0 0" xyz="0 0 0"/>
      <geometry>
        <mesh filename="file:///home/kpdudek/Robotics/src/ar3/urdf/meshes/Link5.dae"/>
      </geometry>
    </collision>
    <visual>
      <origin rpy="0 0 0" xyz="0 0 0"/>
      <geometry>
        <mesh filename="file:///home/kpdudek/Robotics/src/ar3/urdf/meshes/Link5.dae"/>
      </geometry>
    </visual>
  </link>
  <!-- JOINT 5 -->
  <joint name="joint5" type="revolute">
    <parent link="link4"/>
    <child link="link5"/>
    <origin rpy="0 0 0" xyz="0 0 0.172"/>
    <axis xyz="1 0 0"/>
    <dynamics damping="0.7"/>
    <limit effort="30.0" lower="-1.4" upper="1.4" velocity="10.0"/>
  </joint>
  <!-- LINK 6-->
  <link name="link6">
    <collision>
      <origin rpy="0 0 0" xyz="0 0 0"/>
      <geometry>
        <mesh filename="file:///home/kpdudek/Robotics/src/ar3/urdf/meshes/Link6.dae"/>
      </geometry>
    </collision>
    <visual>
      <origin rpy="0 0 0" xyz="0 0 0"/>
      <geometry>
        <mesh filename="file:///home/kpdudek/Robotics/src/ar3/urdf/meshes/Link6.dae"/>
      </geometry>
    </visual>
  </link>
  <!-- JOINT 6 -->
  <joint name="joint6" type="revolute">
    <parent link="link5"/>
    <child link="link6"/>
    <origin rpy="0 0 0" xyz="0 0 0.015"/>
    <axis xyz="0 0 1"/>
    <dynamics damping="0.7"/>
    <limit effort="30.0" lower="-3.14" upper="3.14" velocity="10.0"/>
  </joint>
  <!-- Flange Frame -->
  <link name="flange"/>
  <!-- Flange joint -->
  <joint name="flange_joint" type="fixed">
    <parent link="link6"/>
    <child link="flange"/>
    <origin rpy="0 0 0" xyz="-0.0 0.0 0.016"/>
    <axis xyz="0 0 1"/>
  </joint>
  <!-- EOAT -->
  <link name="eoat">
    <collision>
      <origin rpy="0 0 0" xyz="0 0 0"/>
      <geometry>
        <mesh filename="file:///home/kpdudek/Robotics/src/ar3/urdf/meshes/gripper.dae"/>
      </geometry>
    </collision>
    <visual>
      <origin rpy="0 0 0" xyz="0 0 0"/>
      <geometry>
        <mesh filename="file:///home/kpdudek/Robotics/src/ar3/urdf/meshes/gripper.dae"/>
      </geometry>
      <!--  -->
    </visual>
  </link>
  <!-- EOAT Joint -->
  <joint name="eoat_joint" type="fixed">
    <parent link="flange"/>
    <child link="eoat"/>
    <origin rpy="0 0 0" xyz="0 0 0"/>
    <axis xyz="0 0 1"/>
  </joint>
  <!-- TCP Frame -->
  <link name="tcp"/>
  <!-- Flange joint -->
  <joint name="tcp_joint" type="fixed">
    <parent link="flange"/>
    <child link="tcp"/>
    <origin rpy="0 0 0" xyz="-0.0 0.0 0.08261"/>
    <axis xyz="0 0 1"/>
  </joint>
  <!-- END OF ROBOT -->
</robot>
