<?xml version="1.0"?>
<!-- Revolute-Revolute Manipulator -->
<robot name="ar3" xmlns:xacro="http://www.ros.org/wiki/xacro">

  <!-- Constants for robot dimensions -->
  <xacro:property name="PI" value="3.1415926535897931"/>
  <xacro:property name="mass" value="1.2" /> 
  <xacro:property name="width" value="0.1" /> 
  <xacro:property name="height1" value=".1397" /> 
  <xacro:property name="height2" value="0.206" /> 
  <xacro:property name="height3" value="0.227" /> 
  <xacro:property name="height4" value="0.1" /> 

  <!-- Joint offsets -->
  <xacro:property name="joint1_x" value="0"/>
  <xacro:property name="joint1_y" value="0"/>
  <xacro:property name="joint1_z" value="0"/>
  
  <xacro:property name="joint2_x" value=".0508"/>
  <xacro:property name="joint2_y" value="-.06786547"/>
  <xacro:property name="joint2_z" value=".13907540"/>

  <xacro:property name="joint3_x" value="-.015"/>
  <xacro:property name="joint3_y" value="0"/>
  <xacro:property name="joint3_z" value=".305"/>

  <xacro:property name="joint4_x" value="-0.036"/>
  <xacro:property name="joint4_y" value="0"/>
  <xacro:property name="joint4_z" value="0.05"/>

  <xacro:property name="joint5_x" value="0"/>
  <xacro:property name="joint5_y" value="0"/>
  <xacro:property name="joint5_z" value="0.172"/>

  <xacro:property name="joint6_x" value="0"/>
  <xacro:property name="joint6_y" value="0"/>
  <xacro:property name="joint6_z" value="0.015"/>

  <!-- Import all Gazebo-customization elements, including Gazebo colors -->
  <xacro:include filename="$(find ar3)/urdf/AR3.gazebo" />

  <!-- BASE -->
  <link name="base">
    <collision>
      <origin xyz="0 0 0" rpy="0 0 0"/>
      <geometry>
	      <mesh filename="$(find ar3)/urdf/meshes/Base.stl" scale=".001 .001 .001"/>
      </geometry>
    </collision>

    <visual>
      <origin xyz="0 0 0" rpy="0 0 0"/>
      <geometry>
	      <mesh filename="$(find ar3)/urdf/meshes/Base.stl" scale=".001 .001 .001"/>
      </geometry>
      <material name="orange"/>
    </visual>

    <inertial>
      <origin xyz="0 0 0" rpy="0 0 0"/>
      <mass value="${mass}"/>
      <inertia
	      ixx="${mass / 12.0 * (width*width + height1*height1)}" ixy="0.0" ixz="0.0"
	      iyy="${mass / 12.0 * (height1*height1 + width*width)}" iyz="0.0"
	      izz="${mass / 12.0 * (width*width + width*width)}"/>
    </inertial>
  </link>

  <!-- Link 1 -->
  <link name="link1">
    <collision>
      <origin xyz="0 0 0" rpy="0 0 0"/>
      <geometry>
	      <mesh filename="$(find ar3)/urdf/meshes/Link1.stl" scale=".001 .001 .001"/>
      </geometry>
    </collision>

    <visual>
      <origin xyz="0 0 0" rpy="0 0 0"/>
      <geometry>
	      <mesh filename="$(find ar3)/urdf/meshes/Link1.stl" scale=".001 .001 .001"/>
      </geometry>
      <material name="orange"/>
    </visual>

    <inertial>
      <origin xyz="0 0 0" rpy="0 0 0"/>
      <mass value="${mass}"/>
      <inertia
	      ixx="${mass / 12.0 * (width*width + height1*height1)}" ixy="0.0" ixz="0.0"
	      iyy="${mass / 12.0 * (height1*height1 + width*width)}" iyz="0.0"
	      izz="${mass / 12.0 * (width*width + width*width)}"/>
    </inertial>
  </link>

  <!-- JOINT 1 -->
  <joint name="joint1" type="revolute">
    <parent link="base"/>
    <child link="link1"/>
    <origin xyz="${joint1_x} ${joint1_y} ${joint1_z}" rpy="0 0 0"/>
    <axis xyz="0 0 1"/>
    <dynamics damping="0.7"/>
    <limit lower="-2.0" upper="2.0" effort="30.0" velocity="10.0"/>
  </joint>

  <!-- Link 2 -->
  <link name="link2">
    <collision>
      <origin xyz="0 0 0" rpy="0 0 0"/>
      <geometry>
	      <mesh filename="$(find ar3)/urdf/meshes/Link2.stl" scale=".001 .001 .001"/>
      </geometry>
    </collision>

    <visual>
      <origin xyz="0 0 0" rpy="0 0 0"/>
      <geometry>
	      <mesh filename="$(find ar3)/urdf/meshes/Link2.stl" scale=".001 .001 .001"/>
      </geometry>
      <material name="blue"/>
    </visual>

    <inertial>
      <origin xyz="0 0 0" rpy="0 0 0"/>
      <mass value="${mass}"/>
      <inertia
	      ixx="${mass / 3.0 * (width*width + height2*height2)}" ixy="0.0" ixz="0.0"
	      iyy="${mass / 3.0 * (height2*height2 + width*width)}" iyz="0.0"
	      izz="${mass / 3.0 * (width*width + width*width)}"/>
    </inertial>
  </link>

  <!-- JOINT 2 -->
  <joint name="joint2" type="revolute">
    <parent link="link1"/>
    <child link="link2"/>
    <origin xyz="${joint2_x} ${joint2_y} ${joint2_z}" rpy="0 0 0"/>
    <axis xyz="1 0 0"/>
    <dynamics damping="0.7"/>
    <limit lower="-2.0" upper="2.0" effort="30.0" velocity="10.0"/>
  </joint>

  <!-- Link 3 -->
  <link name="link3">
    <collision>
      <origin xyz="0 0 0" rpy="0 0 0"/>
      <geometry>
	      <mesh filename="$(find ar3)/urdf/meshes/Link3.stl" scale=".001 .001 .001"/>
      </geometry>
    </collision>

    <visual>
      <origin xyz="0 0 0" rpy="0 0 0"/>
      <geometry>
	      <mesh filename="$(find ar3)/urdf/meshes/Link3.stl" scale=".001 .001 .001"/>
      </geometry>
      <material name="orange"/>
    </visual>

    <inertial>
      <origin xyz="0 0 0" rpy="0 0 0"/>
      <mass value="${mass}"/>
      <inertia
	      ixx="${mass / 3.0 * (width*width + height3*height3)}" ixy="0.0" ixz="0.0"
	      iyy="${mass / 3.0 * (height3*height3 + width*width)}" iyz="0.0"
	      izz="${mass / 3.0 * (width*width + width*width)}"/>
    </inertial>
  </link>

  <!-- JOINT 3 -->
  <joint name="joint3" type="revolute">
    <parent link="link2"/>
    <child link="link3"/>
    <origin xyz="${joint3_x} ${joint3_y} ${joint3_z}" rpy="0 0 0"/>
    <axis xyz="1 0 0"/>
    <dynamics damping="0.7"/>
    <limit lower="-2.0" upper="2.0" effort="30.0" velocity="10.0"/>
  </joint>

  <!-- LINK 4-->
  <link name="link4">
    <collision>
      <origin xyz="0 0 0" rpy="0 0 0"/>
      <geometry>
	      <mesh filename="$(find ar3)/urdf/meshes/Link4.stl" scale=".001 .001 .001"/>
      </geometry>
    </collision>

    <visual>
      <origin xyz="0 0 0" rpy="0 0 0"/>
      <geometry>
	      <mesh filename="$(find ar3)/urdf/meshes/Link4.stl" scale=".001 .001 .001"/>
      </geometry>
      <material name="blue"/>
    </visual>

    <inertial>
      <origin xyz="0 0 0" rpy="0 0 0"/>
      <mass value="${mass}"/>
      <inertia
	      ixx="${mass / 12.0 * (width*width + height4*height4)}" ixy="0.0" ixz="0.0"
	      iyy="${mass / 12.0 * (height4*height4 + width*width)}" iyz="0.0"
	      izz="${mass / 12.0 * (width*width + width*width)}"/>
    </inertial>
  </link>

  <!-- JOINT 4 -->
  <joint name="joint4" type="revolute">
    <parent link="link3"/>
    <child link="link4"/>
    <origin xyz="${joint4_x} ${joint4_y} ${joint4_z}" rpy="0 0 0"/>
    <axis xyz="0 0 1"/>
    <dynamics damping="0.7"/>
    <limit lower="-2.0" upper="2.0" effort="30.0" velocity="10.0"/>
  </joint>

  <!-- LINK 5-->
  <link name="link5">
    <collision>
      <origin xyz="0 0 0" rpy="0 0 0"/>
      <geometry>
	      <mesh filename="$(find ar3)/urdf/meshes/Link5.stl" scale=".001 .001 .001"/>
      </geometry>
    </collision>

    <visual>
      <origin xyz="0 0 0" rpy="0 0 0"/>
      <geometry>
	      <mesh filename="$(find ar3)/urdf/meshes/Link5.stl" scale=".001 .001 .001"/>
      </geometry>
      <material name="orange"/>
    </visual>

    <inertial>
      <origin xyz="0 0 0" rpy="0 0 0"/>
      <mass value="${mass}"/>
      <inertia
	      ixx="${mass / 12.0 * (width*width + height4*height4)}" ixy="0.0" ixz="0.0"
	      iyy="${mass / 12.0 * (height4*height4 + width*width)}" iyz="0.0"
	      izz="${mass / 12.0 * (width*width + width*width)}"/>
    </inertial>
  </link>

  <!-- JOINT 5 -->
  <joint name="joint5" type="revolute">
    <parent link="link4"/>
    <child link="link5"/>
    <origin xyz="${joint5_x} ${joint5_y} ${joint5_z}" rpy="0 0 0"/>
    <axis xyz="1 0 0"/>
    <dynamics damping="0.7"/>
    <limit lower="-2.0" upper="2.0" effort="30.0" velocity="10.0"/>
  </joint>

  <!-- LINK 6-->
  <link name="link6">
    <collision>
      <origin xyz="0 0 0" rpy="0 0 0"/>
      <geometry>
	      <mesh filename="$(find ar3)/urdf/meshes/Link6.stl" scale=".001 .001 .001"/>
      </geometry>
    </collision>

    <visual>
      <origin xyz="0 0 0" rpy="0 0 0"/>
      <geometry>
	      <mesh filename="$(find ar3)/urdf/meshes/Link6.stl" scale=".001 .001 .001"/>
      </geometry>
      <material name="blue"/>
    </visual>

    <inertial>
      <origin xyz="0 0 0" rpy="0 0 0"/>
      <mass value="${mass}"/>
      <inertia
	      ixx="${mass / 12.0 * (width*width + height4*height4)}" ixy="0.0" ixz="0.0"
	      iyy="${mass / 12.0 * (height4*height4 + width*width)}" iyz="0.0"
	      izz="${mass / 12.0 * (width*width + width*width)}"/>
    </inertial>
  </link>

  <!-- JOINT 6 -->
  <joint name="joint6" type="revolute">
    <parent link="link5"/>
    <child link="link6"/>
    <origin xyz="${joint6_x} ${joint6_y} ${joint6_z}" rpy="0 0 0"/>
    <axis xyz="0 0 1"/>
    <dynamics damping="0.7"/>
    <limit lower="-2.0" upper="2.0" effort="30.0" velocity="10.0"/>
  </joint>

<!-- END OF ROBOT -->
</robot>
