<?xml version="1.0" encoding="utf-8"?>
<!-- =================================================================================== -->
<!-- |    This document was autogenerated by xacro from AR3_noGazebo.xacro             | -->
<!-- |    EDITING THIS FILE BY HAND IS NOT RECOMMENDED                                 | -->
<!-- =================================================================================== -->
<!-- Revolute-Revolute Manipulator -->
<robot name="ar3">
  <material name="black">
    <color rgba="0.0 0.0 0.0 1.0"/>
  </material>
  <material name="blue">
    <color rgba="0.0 0.0 0.8 1.0"/>
  </material>
  <material name="green">
    <color rgba="0.0 0.8 0.0 1.0"/>
  </material>
  <material name="grey">
    <color rgba="0.2 0.2 0.2 1.0"/>
  </material>
  <material name="orange">
    <color rgba="1.0 0.423529411765 0.0392156862745 1.0"/>
  </material>
  <material name="brown">
    <color rgba="0.870588235294 0.811764705882 0.764705882353 1.0"/>
  </material>
  <material name="red">
    <color rgba="0.8 0.0 0.0 1.0"/>
  </material>
  <material name="white">
    <color rgba="1.0 1.0 1.0 1.0"/>
  </material>
  <!-- Used for fixing robot to Gazebo 'base_link' -->
  <link name="world"/>
  <!-- ros_control plugin -->
  <gazebo>
    <plugin filename="libgazebo_ros_control.so" name="gazebo_ros_control">
      <robotNamespace>/rrbot</robotNamespace>
      <robotSimType>gazebo_ros_control/DefaultRobotHWSim</robotSimType>
    </plugin>
  </gazebo>
  <!-- Stand -->
  <gazebo reference="stand">
    <material>Gazebo/DarkGrey</material>
  </gazebo>
  <!-- Stand -->
  <gazebo reference="shelving">
    <material>Gazebo/White</material>
  </gazebo>
  <!-- Base -->
  <gazebo reference="base">
    <material>Gazebo/Blue</material>
  </gazebo>
  <!-- Link1 -->
  <gazebo reference="link1">
    <material>Gazebo/Orange</material>
  </gazebo>
  <!-- Link2 -->
  <gazebo reference="link2">
    <mu1>0.2</mu1>
    <mu2>0.2</mu2>
    <material>Gazebo/Blue</material>
  </gazebo>
  <!-- Link3 -->
  <gazebo reference="link3">
    <mu1>0.2</mu1>
    <mu2>0.2</mu2>
    <material>Gazebo/Orange</material>
  </gazebo>
  <!-- Link4 -->
  <gazebo reference="link4">
    <mu1>0.2</mu1>
    <mu2>0.2</mu2>
    <material>Gazebo/Blue</material>
  </gazebo>
  <!-- Link5 -->
  <gazebo reference="link5">
    <mu1>0.2</mu1>
    <mu2>0.2</mu2>
    <material>Gazebo/Orange</material>
  </gazebo>
  <!-- Link6 -->
  <gazebo reference="link6">
    <mu1>0.2</mu1>
    <mu2>0.2</mu2>
    <material>Gazebo/Blue</material>
  </gazebo>
  <!-- BASE -->
  <link name="base">
    <collision>
      <origin rpy="0 0 0" xyz="0 0 0"/>
      <geometry>
        <mesh filename="file:///home/kurt/Robotics/src/ar3/urdf/meshes/Base.stl" scale=".001 .001 .001"/>
      </geometry>
    </collision>
    <visual>
      <origin rpy="0 0 0" xyz="0 0 0"/>
      <geometry>
        <mesh filename="file:///home/kurt/Robotics/src/ar3/urdf/meshes/Base.stl" scale=".001 .001 .001"/>
      </geometry>
      <material name="orange"/>
    </visual>
    <inertial>
      <origin rpy="0 0 0" xyz="0 0 0"/>
      <mass value="1.2"/>
      <inertia ixx="0.002951609" ixy="0.0" ixz="0.0" iyy="0.002951609" iyz="0.0" izz="0.002"/>
    </inertial>
  </link>
  <!-- Link 1 -->
  <link name="link1">
    <collision>
      <origin rpy="0 0 0" xyz="0 0 0"/>
      <geometry>
        <mesh filename="file:///home/kurt/Robotics/src/ar3/urdf/meshes/Link1.stl" scale=".001 .001 .001"/>
      </geometry>
    </collision>
    <visual>
      <origin rpy="0 0 0" xyz="0 0 0"/>
      <geometry>
        <mesh filename="file:///home/kurt/Robotics/src/ar3/urdf/meshes/Link1.stl" scale=".001 .001 .001"/>
      </geometry>
      <material name="orange"/>
    </visual>
    <inertial>
      <origin rpy="0 0 0" xyz="0 0 0"/>
      <mass value="1.2"/>
      <inertia ixx="0.002951609" ixy="0.0" ixz="0.0" iyy="0.002951609" iyz="0.0" izz="0.002"/>
    </inertial>
  </link>
  <!-- JOINT 1 -->
  <joint name="joint1" type="revolute">
    <parent link="base"/>
    <child link="link1"/>
    <origin rpy="0 0 0" xyz="0 0 0"/>
    <axis xyz="0 0 1"/>
    <dynamics damping="0.7"/>
    <limit effort="30.0" lower="-2.0" upper="2.0" velocity="10.0"/>
  </joint>
  <!-- Link 2 -->
  <link name="link2">
    <collision>
      <origin rpy="0 0 0" xyz="0 0 0"/>
      <geometry>
        <mesh filename="file:///home/kurt/Robotics/src/ar3/urdf/meshes/Link2.stl" scale=".001 .001 .001"/>
      </geometry>
    </collision>
    <visual>
      <origin rpy="0 0 0" xyz="0 0 0"/>
      <geometry>
        <mesh filename="file:///home/kurt/Robotics/src/ar3/urdf/meshes/Link2.stl" scale=".001 .001 .001"/>
      </geometry>
      <material name="blue"/>
    </visual>
    <inertial>
      <origin rpy="0 0 0" xyz="0 0 0"/>
      <mass value="1.2"/>
      <inertia ixx="0.0209744" ixy="0.0" ixz="0.0" iyy="0.0209744" iyz="0.0" izz="0.008"/>
    </inertial>
  </link>
  <!-- JOINT 2 -->
  <joint name="joint2" type="revolute">
    <parent link="link1"/>
    <child link="link2"/>
    <origin rpy="0 0 0" xyz="0.0508 -0.06786547 0.1390754"/>
    <axis xyz="1 0 0"/>
    <dynamics damping="0.7"/>
    <limit effort="30.0" lower="-2.0" upper="2.0" velocity="10.0"/>
  </joint>
  <!-- Link 3 -->
  <link name="link3">
    <collision>
      <origin rpy="0 0 0" xyz="0 0 0"/>
      <geometry>
        <mesh filename="file:///home/kurt/Robotics/src/ar3/urdf/meshes/Link3.stl" scale=".001 .001 .001"/>
      </geometry>
    </collision>
    <visual>
      <origin rpy="0 0 0" xyz="0 0 0"/>
      <geometry>
        <mesh filename="file:///home/kurt/Robotics/src/ar3/urdf/meshes/Link3.stl" scale=".001 .001 .001"/>
      </geometry>
      <material name="orange"/>
    </visual>
    <inertial>
      <origin rpy="0 0 0" xyz="0 0 0"/>
      <mass value="1.2"/>
      <inertia ixx="0.0246116" ixy="0.0" ixz="0.0" iyy="0.0246116" iyz="0.0" izz="0.008"/>
    </inertial>
  </link>
  <!-- JOINT 3 -->
  <joint name="joint3" type="revolute">
    <parent link="link2"/>
    <child link="link3"/>
    <origin rpy="0 0 0" xyz="-0.015 0 0.305"/>
    <axis xyz="1 0 0"/>
    <dynamics damping="0.7"/>
    <limit effort="30.0" lower="-2.0" upper="2.0" velocity="10.0"/>
  </joint>
  <!-- LINK 4-->
  <link name="link4">
    <collision>
      <origin rpy="0 0 0" xyz="0 0 0"/>
      <geometry>
        <mesh filename="file:///home/kurt/Robotics/src/ar3/urdf/meshes/Link4.stl" scale=".001 .001 .001"/>
      </geometry>
    </collision>
    <visual>
      <origin rpy="0 0 0" xyz="0 0 0"/>
      <geometry>
        <mesh filename="file:///home/kurt/Robotics/src/ar3/urdf/meshes/Link4.stl" scale=".001 .001 .001"/>
      </geometry>
      <material name="blue"/>
    </visual>
    <inertial>
      <origin rpy="0 0 0" xyz="0 0 0"/>
      <mass value="1.2"/>
      <inertia ixx="0.002" ixy="0.0" ixz="0.0" iyy="0.002" iyz="0.0" izz="0.002"/>
    </inertial>
  </link>
  <!-- JOINT 4 -->
  <joint name="joint4" type="revolute">
    <parent link="link3"/>
    <child link="link4"/>
    <origin rpy="0 0 0" xyz="-0.036 0 0.05"/>
    <axis xyz="0 0 1"/>
    <dynamics damping="0.7"/>
    <limit effort="30.0" lower="-2.0" upper="2.0" velocity="10.0"/>
  </joint>
  <!-- LINK 5-->
  <link name="link5">
    <collision>
      <origin rpy="0 0 0" xyz="0 0 0"/>
      <geometry>
        <mesh filename="file:///home/kurt/Robotics/src/ar3/urdf/meshes/Link5.stl" scale=".001 .001 .001"/>
      </geometry>
    </collision>
    <visual>
      <origin rpy="0 0 0" xyz="0 0 0"/>
      <geometry>
        <mesh filename="file:///home/kurt/Robotics/src/ar3/urdf/meshes/Link5.stl" scale=".001 .001 .001"/>
      </geometry>
      <material name="orange"/>
    </visual>
    <inertial>
      <origin rpy="0 0 0" xyz="0 0 0"/>
      <mass value="1.2"/>
      <inertia ixx="0.002" ixy="0.0" ixz="0.0" iyy="0.002" iyz="0.0" izz="0.002"/>
    </inertial>
  </link>
  <!-- JOINT 5 -->
  <joint name="joint5" type="revolute">
    <parent link="link4"/>
    <child link="link5"/>
    <origin rpy="0 0 0" xyz="0 0 0.172"/>
    <axis xyz="1 0 0"/>
    <dynamics damping="0.7"/>
    <limit effort="30.0" lower="-2.0" upper="2.0" velocity="10.0"/>
  </joint>
  <!-- LINK 6-->
  <link name="link6">
    <collision>
      <origin rpy="0 0 0" xyz="0 0 0"/>
      <geometry>
        <mesh filename="file:///home/kurt/Robotics/src/ar3/urdf/meshes/Link6.stl" scale=".001 .001 .001"/>
      </geometry>
    </collision>
    <visual>
      <origin rpy="0 0 0" xyz="0 0 0"/>
      <geometry>
        <mesh filename="file:///home/kurt/Robotics/src/ar3/urdf/meshes/Link6.stl" scale=".001 .001 .001"/>
      </geometry>
      <material name="blue"/>
    </visual>
    <inertial>
      <origin rpy="0 0 0" xyz="0 0 0"/>
      <mass value="1.2"/>
      <inertia ixx="0.002" ixy="0.0" ixz="0.0" iyy="0.002" iyz="0.0" izz="0.002"/>
    </inertial>
  </link>
  <!-- JOINT 6 -->
  <joint name="joint6" type="revolute">
    <parent link="link5"/>
    <child link="link6"/>
    <origin rpy="0 0 0" xyz="0 0 0.015"/>
    <axis xyz="0 0 1"/>
    <dynamics damping="0.7"/>
    <limit effort="30.0" lower="-2.0" upper="2.0" velocity="10.0"/>
  </joint>
  <!-- END OF ROBOT -->
  <!-- Robot to Environment-->
  <joint name="BaseJoint" type="fixed">
    <parent link="world"/>
    <child link="base"/>
    <origin rpy="0 0 0" xyz="0 0 0"/>
    <axis xyz="0 0 1"/>
    <dynamics damping="0.7"/>
  </joint>
  <!-- Flange Frame -->
  <link name="flange"/>
  <!-- Flange joint -->
  <joint name="flange_joint" type="fixed">
    <parent link="link6"/>
    <child link="flange"/>
    <origin rpy="0 0 0" xyz="-0.003 0.020066 0.078"/>
    <axis xyz="0 0 1"/>
    <dynamics damping="0.7"/>
  </joint>
  <!-- END OF ROBOT -->
</robot>
